<p>从finally语句块内抛出的异常会覆盖之前在 <code>try</code> 或 <code>catch</code> 语句块中抛出的异常，并且，被覆盖异常的信息和堆栈跟踪内容（stack trace）也会丢失。</p>
<h2>不合规的代码示例</h2>
<pre>
try
{
  /* 此处是一些在结束时抛出异常的操作 */
  throw new ArgumentException();
}
finally
{
  /* 清理 */
  throw new InvalidOperationException();       // 不合规，此处会覆盖ArgumentException
}
</pre>
<h2>合规的代码示例</h2>
<pre>
try
{
  /* 此处是一些在结束时抛出异常的操作 */
  throw new ArgumentException();
}
finally
{
  /* 清理 */                       // 合规
}
</pre>
<h2>请参阅</h2>
<ul>
  <li> <a href="https://www.securecoding.cert.org/confluence/x/soUbAQ">CERT, ERR05-J.</a> - Do not let checked exceptions escape from a finally block
  </li>
</ul>

